
ERROR - 2023-04-21 02:27:38,399

403 Client Error: Forbidden for url: https://actions-api.stackspot.com/actions/v1
Traceback (most recent call last):
  File "actions/list.py", line 29, in get_actions_of_org
  File "actions/list.py", line 51, in __get_all_actions
  File "requests/models.py", line 1021, in raise_for_status
requests.exceptions.HTTPError: 403 Client Error: Forbidden for url: https://actions-api.stackspot.com/actions/v1

ERROR - 2023-04-21 02:27:38,401

Couldn't retrieve actions for your organization.
Traceback (most recent call last):
  File "actions/list.py", line 29, in get_actions_of_org
  File "actions/list.py", line 51, in __get_all_actions
  File "requests/models.py", line 1021, in raise_for_status
requests.exceptions.HTTPError: 403 Client Error: Forbidden for url: https://actions-api.stackspot.com/actions/v1

During handling of the above exception, another exception occurred:

Traceback (most recent call last):
  File "actions/caching.py", line 27, in cache_actions
  File "actions/list.py", line 35, in get_actions_of_org
templateframework.exception.business_exception.BusinessException: Couldn't retrieve actions for your organization.

ERROR - 2023-04-21 02:27:38,401

Couldn't retrieve actions for your organization.
Traceback (most recent call last):
  File "actions/list.py", line 29, in get_actions_of_org
  File "actions/list.py", line 51, in __get_all_actions
  File "requests/models.py", line 1021, in raise_for_status
requests.exceptions.HTTPError: 403 Client Error: Forbidden for url: https://actions-api.stackspot.com/actions/v1

During handling of the above exception, another exception occurred:

Traceback (most recent call last):
  File "actions/caching.py", line 27, in cache_actions
  File "actions/list.py", line 35, in get_actions_of_org
templateframework.exception.business_exception.BusinessException: Couldn't retrieve actions for your organization.

ERROR - 2023-04-21 02:29:06,630

403 Client Error: Forbidden for url: https://actions-api.stackspot.com/actions/v1
Traceback (most recent call last):
  File "actions/list.py", line 29, in get_actions_of_org
  File "actions/list.py", line 51, in __get_all_actions
  File "requests/models.py", line 1021, in raise_for_status
requests.exceptions.HTTPError: 403 Client Error: Forbidden for url: https://actions-api.stackspot.com/actions/v1

ERROR - 2023-04-21 02:29:06,631

Couldn't retrieve actions for your organization.
Traceback (most recent call last):
  File "actions/list.py", line 29, in get_actions_of_org
  File "actions/list.py", line 51, in __get_all_actions
  File "requests/models.py", line 1021, in raise_for_status
requests.exceptions.HTTPError: 403 Client Error: Forbidden for url: https://actions-api.stackspot.com/actions/v1

During handling of the above exception, another exception occurred:

Traceback (most recent call last):
  File "actions/caching.py", line 27, in cache_actions
  File "actions/list.py", line 35, in get_actions_of_org
templateframework.exception.business_exception.BusinessException: Couldn't retrieve actions for your organization.

ERROR - 2023-04-21 02:29:06,631

Couldn't retrieve actions for your organization.
Traceback (most recent call last):
  File "actions/list.py", line 29, in get_actions_of_org
  File "actions/list.py", line 51, in __get_all_actions
  File "requests/models.py", line 1021, in raise_for_status
requests.exceptions.HTTPError: 403 Client Error: Forbidden for url: https://actions-api.stackspot.com/actions/v1

During handling of the above exception, another exception occurred:

Traceback (most recent call last):
  File "actions/caching.py", line 27, in cache_actions
  File "actions/list.py", line 35, in get_actions_of_org
templateframework.exception.business_exception.BusinessException: Couldn't retrieve actions for your organization.

ERROR - 2023-04-21 17:09:15,219

Login with a client ID. The client KEY is required to use STK CLI in CI/CD pipeline.
Traceback (most recent call last):
  File "cli.py", line 109, in main
  File "click/core.py", line 1130, in __call__
  File "i18n/base_i18n_command.py", line 113, in main
  File "click/core.py", line 1654, in invoke
  File "click/core.py", line 1404, in invoke
  File "click/core.py", line 760, in invoke
  File "click/decorators.py", line 26, in new_func
  File "cli.py", line 71, in cli
  File "core/auth.py", line 46, in check_tokens
  File "core/auth.py", line 76, in check_session_tokens
templateframework.exception.business_exception.BusinessException: Login with a client ID. The client KEY is required to use STK CLI in CI/CD pipeline.

ERROR - 2023-04-21 17:10:23,834

403 Client Error: Forbidden for url: https://actions-api.stackspot.com/actions/v1
Traceback (most recent call last):
  File "actions/list.py", line 29, in get_actions_of_org
  File "actions/list.py", line 51, in __get_all_actions
  File "requests/models.py", line 1021, in raise_for_status
requests.exceptions.HTTPError: 403 Client Error: Forbidden for url: https://actions-api.stackspot.com/actions/v1

ERROR - 2023-04-21 17:10:23,835

Couldn't retrieve actions for your organization.
Traceback (most recent call last):
  File "actions/list.py", line 29, in get_actions_of_org
  File "actions/list.py", line 51, in __get_all_actions
  File "requests/models.py", line 1021, in raise_for_status
requests.exceptions.HTTPError: 403 Client Error: Forbidden for url: https://actions-api.stackspot.com/actions/v1

During handling of the above exception, another exception occurred:

Traceback (most recent call last):
  File "actions/caching.py", line 27, in cache_actions
  File "actions/list.py", line 35, in get_actions_of_org
templateframework.exception.business_exception.BusinessException: Couldn't retrieve actions for your organization.

ERROR - 2023-04-21 17:10:23,835

Couldn't retrieve actions for your organization.
Traceback (most recent call last):
  File "actions/list.py", line 29, in get_actions_of_org
  File "actions/list.py", line 51, in __get_all_actions
  File "requests/models.py", line 1021, in raise_for_status
requests.exceptions.HTTPError: 403 Client Error: Forbidden for url: https://actions-api.stackspot.com/actions/v1

During handling of the above exception, another exception occurred:

Traceback (most recent call last):
  File "actions/caching.py", line 27, in cache_actions
  File "actions/list.py", line 35, in get_actions_of_org
templateframework.exception.business_exception.BusinessException: Couldn't retrieve actions for your organization.

ERROR - 2023-04-21 18:18:17,628

Login with a client ID. The client KEY is required to use STK CLI in CI/CD pipeline.
Traceback (most recent call last):
  File "cli.py", line 109, in main
  File "click/core.py", line 1130, in __call__
  File "i18n/base_i18n_command.py", line 113, in main
  File "click/core.py", line 1654, in invoke
  File "click/core.py", line 1404, in invoke
  File "click/core.py", line 760, in invoke
  File "click/decorators.py", line 26, in new_func
  File "cli.py", line 71, in cli
  File "core/auth.py", line 46, in check_tokens
  File "core/auth.py", line 76, in check_session_tokens
templateframework.exception.business_exception.BusinessException: Login with a client ID. The client KEY is required to use STK CLI in CI/CD pipeline.

ERROR - 2023-04-21 18:19:11,363

403 Client Error: Forbidden for url: https://actions-api.stackspot.com/actions/v1
Traceback (most recent call last):
  File "actions/list.py", line 29, in get_actions_of_org
  File "actions/list.py", line 51, in __get_all_actions
  File "requests/models.py", line 1021, in raise_for_status
requests.exceptions.HTTPError: 403 Client Error: Forbidden for url: https://actions-api.stackspot.com/actions/v1

ERROR - 2023-04-21 18:19:11,365

Couldn't retrieve actions for your organization.
Traceback (most recent call last):
  File "actions/list.py", line 29, in get_actions_of_org
  File "actions/list.py", line 51, in __get_all_actions
  File "requests/models.py", line 1021, in raise_for_status
requests.exceptions.HTTPError: 403 Client Error: Forbidden for url: https://actions-api.stackspot.com/actions/v1

During handling of the above exception, another exception occurred:

Traceback (most recent call last):
  File "actions/caching.py", line 27, in cache_actions
  File "actions/list.py", line 35, in get_actions_of_org
templateframework.exception.business_exception.BusinessException: Couldn't retrieve actions for your organization.

ERROR - 2023-04-21 18:19:11,365

Couldn't retrieve actions for your organization.
Traceback (most recent call last):
  File "actions/list.py", line 29, in get_actions_of_org
  File "actions/list.py", line 51, in __get_all_actions
  File "requests/models.py", line 1021, in raise_for_status
requests.exceptions.HTTPError: 403 Client Error: Forbidden for url: https://actions-api.stackspot.com/actions/v1

During handling of the above exception, another exception occurred:

Traceback (most recent call last):
  File "actions/caching.py", line 27, in cache_actions
  File "actions/list.py", line 35, in get_actions_of_org
templateframework.exception.business_exception.BusinessException: Couldn't retrieve actions for your organization.
